<?xml version="1.0" encoding="utf-8"?>
<!-- This URDF was automatically created by SolidWorks to URDF Exporter! Originally created by Stephen Brawner (brawner@gmail.com)
     Commit Version: 1.6.0-4-g7f85cfe  Build Version: 1.6.7995.38578
     For more information, please see http://wiki.ros.org/sw_urdf_exporter -->
<robot xmlns:xacro="http://www.ros.org/wiki/xacro"
  name="pneumatic_disassembly_uni">
  <xacro:macro name="pneumatic_disassembly_unit" params="prefix">
  <link
    name="${prefix}base_link">
    <inertial>
      <origin
        xyz="-0.000962723146110852 -0.00941206246038881 0.00904344128132023"
        rpy="0 0 0" />
      <mass
        value="10.2857499293179" />
      <inertia
        ixx="0.189504941812513"
        ixy="2.49307117251645E-06"
        ixz="6.39340067903422E-08"
        iyy="0.43347643122773"
        iyz="1.27848580559276E-07"
        izz="0.622461811297848" />
    </inertial>
    <visual>
      <origin
        xyz="0 0 0"
        rpy="0 0 0" />
      <geometry>
        <mesh
          filename="package://pneumatic_disassembly_unit_description/meshes/base_plate_link1.dae" />
      </geometry>
      <material
        name="">
        <color
          rgba="0.752941176470588 0.752941176470588 0.752941176470588 1" />
      </material>
    </visual>
      <collision>
      <origin
        xyz="0 0 0"
        rpy="0 0 0" />
      <geometry>
         <mesh
          filename="package://pneumatic_disassembly_unit_description/meshes/base_plate_link1.dae" />
      </geometry>
      </collision>
  </link>
  <link
    name="${prefix}pull_cylinder_link">
    <inertial>
      <origin
        xyz="0.16987 1.7772E-05 -0.025656"
        rpy="0 0 0" />
      <mass
        value="0.32113" />
      <inertia
        ixx="0.00073667"
        ixy="-2.3741E-08"
        ixz="-8.3707E-07"
        iyy="0.00016166"
        iyz="-5.7752E-09"
        izz="0.00086637" />
    </inertial>
    <visual>
      <origin
        xyz="0 0 0"
        rpy="1.57 0 1.57" />
      <geometry>
        <mesh
          filename="package://pneumatic_disassembly_unit_description/meshes/pull_cylinder_link.dae" />
      </geometry>
      <material
        name="">
        <color
          rgba="0.75294 0.75294 0.75294 1" />
      </material>
    </visual>
    <collision>
        <origin
        xyz="0 0 0"
        rpy="1.57 0 1.57" />
      <geometry>
        <mesh
          filename="package://pneumatic_disassembly_unit_description/meshes/pull_cylinder_link.dae" />
      </geometry>
      </collision>
  </link>
  <joint
    name="${prefix}pull_cylinder_joint"
    type="prismatic">
    <origin
      xyz="-0.40611 -0.079999 0.069"
      rpy="0 0 0" />
    <parent
      link="${prefix}base_link" />
    <child
      link="${prefix}pull_cylinder_link" />
    <axis
      xyz="1 0 0" />
    <limit
      lower="0"
      upper="0.100"
      effort="1000"
      velocity="1000" />
  </joint>
  <link
    name="${prefix}push_cylinder_link">
    <inertial>
      <origin
        xyz="0.24176 8.3845E-06 0.023032"
        rpy="0 0 0" />
      <mass
        value="0.30404" />
      <inertia
        ixx="0.00023476"
        ixy="-3.3899E-09"
        ixz="8.9268E-07"
        iyy="0.00032833"
        iyz="-5.7754E-09"
        izz="0.00052194" />
    </inertial>
    <visual>
      <origin
        xyz="0 0 0"
        rpy="1.57 0 1.57" />
      <geometry>
        <mesh
          filename="package://pneumatic_disassembly_unit_description/meshes/push_cylinder_link.dae" />
      </geometry>
      <material
        name="">
        <color
          rgba="0.75294 0.75294 0.75294 1" />
      </material>
    </visual>
      <collision>
      <origin
        xyz="0 0 0"
        rpy="1.57 0 1.57" />
      <geometry>
          <mesh
          filename="package://pneumatic_disassembly_unit_description/meshes/push_cylinder_link.dae" />
      </geometry>
      </collision>
  </link>
  <joint
    name="${prefix}push_cylinder_joint"
    type="prismatic">
    <origin
      xyz="0.40589 -0.079999 0.069"
      rpy="3.1416 0 3.1416" />
    <parent
      link="${prefix}base_link" />
    <child
      link="${prefix}push_cylinder_link" />
    <axis
      xyz="1 0 0" />
    <limit
      lower="0"
      upper="0.18"
      effort="1000"
      velocity="1000" />
  </joint>
  </xacro:macro>
</robot>
